

<robot name="iii-robot">

    <material name="yellow">
        <color rgba="0.8 0.8 0.2 0.8"/>
    </material>
    <material name="red">
        <color rgba="0.8 0.0 0.0 1.0"/>
    </material>
    <link name="base_link">
        <visual>
            <origin xyz="0.0 0.0 0.0" rpy="0.0 0.0 0.0"/>
            <geometry>
                <box size="0.5 0.3 0.1"/>
            </geometry>
            <material name="yellow"/>
        </visual>
    </link>

    <link name="camera">
        <visual>
            <geometry>
                <box size="0.02 0.05 0.05"/>
            </geometry>
            <material name="red"/>
        </visual>
    </link>

    <joint name="camera2baselink" type="continuous">
        <origin xyz="0.2 0.0 0.075" rpy="0.0 0.0 0.0"/>
        <parent link="base_link"/>
        <child link="camera"/>
        <!-- 旋转 -->
        <axis xyz="0 0 1"/>
        <!-- <limit lower="0.0" upper="0.0" effort="0.0" velocity="0.0"/> -->
    </joint>
    
</robot>