

<robot name="iii-robot">
    <material name="white">
        <color rgba="0.7 0.7 0.7 0.5"/>
    </material>
    <material name="black">
        <color rgba="0.2 0.2 0.2 0.8"/>
    </material>

    <link name="base_footprint">
        <visual>
            <geometry>
                <sphere radius="0.001"/>
            </geometry>
        </visual>
    </link>

    <link name="base_link">
        <visual>
            <geometry>
                <box size="0.2 0.12 0.07"/>
            </geometry>
            <material name="white"/>
        </visual>
    </link>

    <joint name="base_link2base_footprint" type="fixed">
        <parent link="base_footprint"/>
        <child link="base_link"/>
        <!-- <axis xyz="0.0 0.0 0.0"/> -->
        <!-- 车体高度+离地间距 = 0.07/2 +  -->
        <origin xyz="0.0 0.0 0.05"/>
    </joint>

    <link name="left_front_wheel">
        <visual>
            <geometry>
                <cylinder radius="0.025" length="0.02"/>
            </geometry>
            <material name="black"/>
            <origin rpy="1.57 0.0 0.0"/> 
        </visual>
    </link>

    <joint name="left__front_wheel2base_link" type="continuous">
        <parent link="base_link"/>
        <child link="left_front_wheel"/>
        <!-- 平移 z = 车体高度/2 + 离地间距 - 车轮半径 -->
        <origin xyz="0.08 0.06 -0.025"/>
        <!-- 旋转 -->
        <axis xyz="0 1 0"/>
    </joint>

    <link name="right_front_wheel">
        <visual>
            <geometry>
                <cylinder radius="0.025" length="0.02"/>
            </geometry>
            <material name="black"/>
            <origin rpy="1.57 0.0 0.0"/> 
        </visual>
    </link>

    <joint name="right_front_wheel2base_link" type="continuous">
        <parent link="base_link"/>
        <child link="right_front_wheel"/>
        <origin xyz="0.08 -0.06 -0.025"/>
        <axis xyz="0 1 0"/>
    </joint>

    <link name="left_back_wheel">
        <visual>
            <geometry>
                <cylinder radius="0.025" length="0.02"/>
            </geometry>
            <material name="black"/>
            <origin rpy="1.57 0.0 0.0"/> 
        </visual>
    </link>

    <joint name="left_back_wheel2base_link" type="continuous">
        <parent link="base_link"/>
        <child link="left_back_wheel"/>
        <origin xyz="-0.08 0.06 -0.025"/>
        <axis xyz="0 1 0"/>
    </joint>


    <link name="right_back_wheel">
        <visual>
            <geometry>
                <cylinder radius="0.025" length="0.02"/>
            </geometry>
            <material name="black"/>
            <origin rpy="1.57 0.0 0.0"/> 
        </visual>
    </link>

    <joint name="right_back_wheel2base_link" type="continuous">
        <parent link="base_link"/>
        <child link="right_back_wheel"/>
        <origin xyz="-0.08 -0.06 -0.025"/>
        <axis xyz="0 1 0"/>
    </joint>
</robot>